[0m13:09:03.759598 [debug] [MainThread]: Sending event: {'category': 'dbt', 'action': 'invocation', 'label': 'start', 'context': [<snowplow_tracker.self_describing_json.SelfDescribingJson object at 0x1069b07d0>, <snowplow_tracker.self_describing_json.SelfDescribingJson object at 0x1069b2050>, <snowplow_tracker.self_describing_json.SelfDescribingJson object at 0x1069b2310>]}


============================== 13:09:03.761286 | a75ec64b-1e74-4cb6-8a1b-147bd45636f7 ==============================
[0m13:09:03.761286 [info ] [MainThread]: Running with dbt=1.9.3
[0m13:09:03.761603 [debug] [MainThread]: running dbt with arguments {'quiet': 'False', 'log_cache_events': 'False', 'version_check': 'True', 'profiles_dir': '/Users/judeezeh/.dbt', 'target_path': 'None', 'printer_width': '80', 'invocation_command': 'dbt init my_project', 'warn_error_options': 'WarnErrorOptions(include=[], exclude=[])', 'log_path': 'logs', 'cache_selected_only': 'False', 'empty': 'None', 'debug': 'False', 'no_print': 'None', 'write_json': 'True', 'warn_error': 'None', 'use_colors': 'True', 'fail_fast': 'False', 'introspect': 'True', 'indirect_selection': 'eager', 'send_anonymous_usage_stats': 'True', 'static_parser': 'True', 'log_format': 'default', 'use_experimental_parser': 'False', 'partial_parse': 'True'}
[0m13:09:03.770559 [warn ] [MainThread]: [ConfigFolderDirectory]: Unable to parse logging event dictionary. Failed to parse dir field: expected string or bytes-like object, got 'PosixPath'.. Dictionary: {'dir': PosixPath('/Users/judeezeh/.dbt')}
[0m13:09:03.770749 [info ] [MainThread]: Creating dbt configuration folder at 
[0m13:09:03.771546 [debug] [MainThread]: Starter project path: /opt/anaconda3/lib/python3.11/site-packages/dbt/include/starter_project
[0m13:09:03.775204 [info ] [MainThread]: 
Your new dbt project "my_project" was created!

For more information on how to configure the profiles.yml file,
please consult the dbt documentation here:

  https://docs.getdbt.com/docs/configure-your-profile

One more thing:

Need help? Don't hesitate to reach out to us via GitHub issues or on Slack:

  https://community.getdbt.com/

Happy modeling!

[0m13:09:03.775371 [info ] [MainThread]: Setting up your profile.
[0m13:09:12.295956 [error] [MainThread]: Encountered an error:
numpy.dtype size changed, may indicate binary incompatibility. Expected 96 from C header, got 88 from PyObject
[0m13:09:12.310099 [error] [MainThread]: Traceback (most recent call last):
  File "/opt/anaconda3/lib/python3.11/site-packages/dbt/cli/requires.py", line 153, in wrapper
    result, success = func(*args, **kwargs)
                      ^^^^^^^^^^^^^^^^^^^^^
  File "/opt/anaconda3/lib/python3.11/site-packages/dbt/cli/requires.py", line 103, in wrapper
    return func(*args, **kwargs)
           ^^^^^^^^^^^^^^^^^^^^^
  File "/opt/anaconda3/lib/python3.11/site-packages/dbt/cli/main.py", line 477, in init
    results = task.run()
              ^^^^^^^^^^
  File "/opt/anaconda3/lib/python3.11/site-packages/dbt/task/init.py", line 346, in run
    self.setup_profile(profile_name)
  File "/opt/anaconda3/lib/python3.11/site-packages/dbt/task/init.py", line 262, in setup_profile
    self.create_profile_from_target(adapter, profile_name=profile_name)
  File "/opt/anaconda3/lib/python3.11/site-packages/dbt/task/init.py", line 172, in create_profile_from_target
    load_plugin(adapter)
  File "/opt/anaconda3/lib/python3.11/site-packages/dbt/adapters/factory.py", line 239, in load_plugin
    return FACTORY.load_plugin(name)
           ^^^^^^^^^^^^^^^^^^^^^^^^^
  File "/opt/anaconda3/lib/python3.11/site-packages/dbt/adapters/factory.py", line 68, in load_plugin
    mod: Any = import_module("." + name, "dbt.adapters")
               ^^^^^^^^^^^^^^^^^^^^^^^^^^^^^^^^^^^^^^^^^
  File "/opt/anaconda3/lib/python3.11/importlib/__init__.py", line 126, in import_module
    return _bootstrap._gcd_import(name[level:], package, level)
           ^^^^^^^^^^^^^^^^^^^^^^^^^^^^^^^^^^^^^^^^^^^^^^^^^^^^
  File "<frozen importlib._bootstrap>", line 1204, in _gcd_import
  File "<frozen importlib._bootstrap>", line 1176, in _find_and_load
  File "<frozen importlib._bootstrap>", line 1147, in _find_and_load_unlocked
  File "<frozen importlib._bootstrap>", line 690, in _load_unlocked
  File "<frozen importlib._bootstrap_external>", line 940, in exec_module
  File "<frozen importlib._bootstrap>", line 241, in _call_with_frames_removed
  File "/opt/anaconda3/lib/python3.11/site-packages/dbt/adapters/bigquery/__init__.py", line 1, in <module>
    from dbt.adapters.bigquery.column import BigQueryColumn
  File "/opt/anaconda3/lib/python3.11/site-packages/dbt/adapters/bigquery/column.py", line 4, in <module>
    from google.cloud.bigquery import SchemaField
  File "/opt/anaconda3/lib/python3.11/site-packages/google/cloud/bigquery/__init__.py", line 36, in <module>
    from google.cloud.bigquery.client import Client
  File "/opt/anaconda3/lib/python3.11/site-packages/google/cloud/bigquery/client.py", line 72, in <module>
    from google.cloud.bigquery import _job_helpers
  File "/opt/anaconda3/lib/python3.11/site-packages/google/cloud/bigquery/_job_helpers.py", line 47, in <module>
    from google.cloud.bigquery import job
  File "/opt/anaconda3/lib/python3.11/site-packages/google/cloud/bigquery/job/__init__.py", line 27, in <module>
    from google.cloud.bigquery.job.copy_ import CopyJob
  File "/opt/anaconda3/lib/python3.11/site-packages/google/cloud/bigquery/job/copy_.py", line 22, in <module>
    from google.cloud.bigquery.table import TableReference
  File "/opt/anaconda3/lib/python3.11/site-packages/google/cloud/bigquery/table.py", line 29, in <module>
    import pandas  # type: ignore
    ^^^^^^^^^^^^^
  File "/opt/anaconda3/lib/python3.11/site-packages/pandas/__init__.py", line 22, in <module>
    from pandas.compat import is_numpy_dev as _is_numpy_dev  # pyright: ignore # noqa:F401
    ^^^^^^^^^^^^^^^^^^^^^^^^^^^^^^^^^^^^^^^^^^^^^^^^^^^^^^^
  File "/opt/anaconda3/lib/python3.11/site-packages/pandas/compat/__init__.py", line 18, in <module>
    from pandas.compat.numpy import (
  File "/opt/anaconda3/lib/python3.11/site-packages/pandas/compat/numpy/__init__.py", line 4, in <module>
    from pandas.util.version import Version
  File "/opt/anaconda3/lib/python3.11/site-packages/pandas/util/__init__.py", line 2, in <module>
    from pandas.util._decorators import (  # noqa:F401
  File "/opt/anaconda3/lib/python3.11/site-packages/pandas/util/_decorators.py", line 14, in <module>
    from pandas._libs.properties import cache_readonly
  File "/opt/anaconda3/lib/python3.11/site-packages/pandas/_libs/__init__.py", line 13, in <module>
    from pandas._libs.interval import Interval
  File "pandas/_libs/interval.pyx", line 1, in init pandas._libs.interval
ValueError: numpy.dtype size changed, may indicate binary incompatibility. Expected 96 from C header, got 88 from PyObject

[0m13:09:12.318867 [debug] [MainThread]: Resource report: {"command_name": "init", "command_success": false, "command_wall_clock_time": 8.588691, "process_in_blocks": "0", "process_kernel_time": 0.218547, "process_mem_max_rss": "131186688", "process_out_blocks": "0", "process_user_time": 0.735916}
[0m13:09:12.319226 [debug] [MainThread]: Command `dbt init` failed at 13:09:12.319159 after 8.59 seconds
[0m13:09:12.319496 [debug] [MainThread]: Sending event: {'category': 'dbt', 'action': 'invocation', 'label': 'end', 'context': [<snowplow_tracker.self_describing_json.SelfDescribingJson object at 0x106490a90>, <snowplow_tracker.self_describing_json.SelfDescribingJson object at 0x1077d3990>, <snowplow_tracker.self_describing_json.SelfDescribingJson object at 0x1069ca750>]}
[0m13:09:12.319753 [debug] [MainThread]: Flushing usage events
[0m13:09:15.327721 [debug] [MainThread]: An error was encountered while trying to flush usage events
[0m13:11:16.706809 [debug] [MainThread]: Sending event: {'category': 'dbt', 'action': 'invocation', 'label': 'start', 'context': [<snowplow_tracker.self_describing_json.SelfDescribingJson object at 0x104e286d0>, <snowplow_tracker.self_describing_json.SelfDescribingJson object at 0x104e3f250>, <snowplow_tracker.self_describing_json.SelfDescribingJson object at 0x104e3f790>]}


============================== 13:11:16.708331 | 3948d960-d3bd-4991-8be6-c31594d60339 ==============================
[0m13:11:16.708331 [info ] [MainThread]: Running with dbt=1.9.3
[0m13:11:16.708654 [debug] [MainThread]: running dbt with arguments {'log_cache_events': 'False', 'send_anonymous_usage_stats': 'True', 'write_json': 'True', 'log_path': 'logs', 'warn_error_options': 'WarnErrorOptions(include=[], exclude=[])', 'printer_width': '80', 'use_experimental_parser': 'False', 'empty': 'None', 'fail_fast': 'False', 'debug': 'False', 'version_check': 'True', 'quiet': 'False', 'introspect': 'True', 'indirect_selection': 'eager', 'profiles_dir': '/Users/judeezeh/.dbt', 'use_colors': 'True', 'no_print': 'None', 'target_path': 'None', 'static_parser': 'True', 'cache_selected_only': 'False', 'invocation_command': 'dbt init my_project', 'partial_parse': 'True', 'log_format': 'default', 'warn_error': 'None'}
[0m13:11:16.716844 [info ] [MainThread]: A project called my_project already exists here.
[0m13:11:16.717579 [debug] [MainThread]: Resource report: {"command_name": "init", "command_success": true, "command_wall_clock_time": 0.038192667, "process_in_blocks": "0", "process_kernel_time": 0.108263, "process_mem_max_rss": "101761024", "process_out_blocks": "0", "process_user_time": 0.516602}
[0m13:11:16.717807 [debug] [MainThread]: Command `dbt init` succeeded at 13:11:16.717759 after 0.04 seconds
[0m13:11:16.717972 [debug] [MainThread]: Sending event: {'category': 'dbt', 'action': 'invocation', 'label': 'end', 'context': [<snowplow_tracker.self_describing_json.SelfDescribingJson object at 0x104e3ec90>, <snowplow_tracker.self_describing_json.SelfDescribingJson object at 0x104e3fa90>, <snowplow_tracker.self_describing_json.SelfDescribingJson object at 0x1010183d0>]}
[0m13:11:16.718135 [debug] [MainThread]: Flushing usage events
[0m13:11:22.305009 [debug] [MainThread]: An error was encountered while trying to flush usage events
